[30/Apr/2016 21:44:28] ERROR [django.request:284] Internal Server Error: /data/horses/
Traceback (most recent call last):
  File "/usr/lib/python3.5/site-packages/django/core/handlers/base.py", line 123, in get_response
    response = middleware_method(request)
  File "/usr/lib/python3.5/site-packages/django/middleware/locale.py", line 25, in process_request
    request, check_path=self.is_language_prefix_patterns_used)
  File "/usr/lib/python3.5/site-packages/django/utils/functional.py", line 33, in __get__
    res = instance.__dict__[self.name] = self.func(instance)
  File "/usr/lib/python3.5/site-packages/django/middleware/locale.py", line 68, in is_language_prefix_patterns_used
    for url_pattern in get_resolver(None).url_patterns:
  File "/usr/lib/python3.5/site-packages/django/utils/functional.py", line 33, in __get__
    res = instance.__dict__[self.name] = self.func(instance)
  File "/usr/lib/python3.5/site-packages/django/core/urlresolvers.py", line 417, in url_patterns
    patterns = getattr(self.urlconf_module, "urlpatterns", self.urlconf_module)
  File "/usr/lib/python3.5/site-packages/django/utils/functional.py", line 33, in __get__
    res = instance.__dict__[self.name] = self.func(instance)
  File "/usr/lib/python3.5/site-packages/django/core/urlresolvers.py", line 410, in urlconf_module
    return import_module(self.urlconf_name)
  File "/usr/lib/python3.5/importlib/__init__.py", line 126, in import_module
    return _bootstrap._gcd_import(name[level:], package, level)
  File "<frozen importlib._bootstrap>", line 986, in _gcd_import
  File "<frozen importlib._bootstrap>", line 969, in _find_and_load
  File "<frozen importlib._bootstrap>", line 958, in _find_and_load_unlocked
  File "<frozen importlib._bootstrap>", line 673, in _load_unlocked
  File "<frozen importlib._bootstrap_external>", line 662, in exec_module
  File "<frozen importlib._bootstrap>", line 222, in _call_with_frames_removed
  File "/srv/http/mundilfare/mundilfare/urls.py", line 25, in <module>
    url('^i18n/$', django.views.i18n.set_language, name='set_language'),
NameError: name 'django' is not defined
[30/Apr/2016 21:44:29] ERROR [django.request:284] Internal Server Error: /data/horses/
Traceback (most recent call last):
  File "/usr/lib/python3.5/site-packages/django/core/handlers/base.py", line 235, in get_response
    response = middleware_method(request, response)
  File "/usr/lib/python3.5/site-packages/django/middleware/locale.py", line 55, in process_response
    if not (self.is_language_prefix_patterns_used
  File "/usr/lib/python3.5/site-packages/django/utils/functional.py", line 33, in __get__
    res = instance.__dict__[self.name] = self.func(instance)
  File "/usr/lib/python3.5/site-packages/django/middleware/locale.py", line 68, in is_language_prefix_patterns_used
    for url_pattern in get_resolver(None).url_patterns:
  File "/usr/lib/python3.5/site-packages/django/utils/functional.py", line 33, in __get__
    res = instance.__dict__[self.name] = self.func(instance)
  File "/usr/lib/python3.5/site-packages/django/core/urlresolvers.py", line 417, in url_patterns
    patterns = getattr(self.urlconf_module, "urlpatterns", self.urlconf_module)
  File "/usr/lib/python3.5/site-packages/django/utils/functional.py", line 33, in __get__
    res = instance.__dict__[self.name] = self.func(instance)
  File "/usr/lib/python3.5/site-packages/django/core/urlresolvers.py", line 410, in urlconf_module
    return import_module(self.urlconf_name)
  File "/usr/lib/python3.5/importlib/__init__.py", line 126, in import_module
    return _bootstrap._gcd_import(name[level:], package, level)
  File "<frozen importlib._bootstrap>", line 986, in _gcd_import
  File "<frozen importlib._bootstrap>", line 969, in _find_and_load
  File "<frozen importlib._bootstrap>", line 958, in _find_and_load_unlocked
  File "<frozen importlib._bootstrap>", line 673, in _load_unlocked
  File "<frozen importlib._bootstrap_external>", line 662, in exec_module
  File "<frozen importlib._bootstrap>", line 222, in _call_with_frames_removed
  File "/srv/http/mundilfare/mundilfare/urls.py", line 25, in <module>
    url('^i18n/$', django.views.i18n.set_language, name='set_language'),
NameError: name 'django' is not defined
[30/Apr/2016 21:55:31] ERROR [django.request:284] Internal Server Error: /data/horses/
Traceback (most recent call last):
  File "/usr/lib/python3.5/site-packages/django/core/handlers/base.py", line 134, in get_response
    resolver_match = resolver.resolve(request.path_info)
  File "/usr/lib/python3.5/site-packages/django/core/urlresolvers.py", line 376, in resolve
    sub_match = pattern.resolve(new_path)
AttributeError: 'str' object has no attribute 'resolve'
[30/Apr/2016 21:58:57] ERROR [django.request:284] Internal Server Error: /
Traceback (most recent call last):
  File "/usr/lib/python3.5/site-packages/django/core/handlers/base.py", line 134, in get_response
    resolver_match = resolver.resolve(request.path_info)
  File "/usr/lib/python3.5/site-packages/django/core/urlresolvers.py", line 376, in resolve
    sub_match = pattern.resolve(new_path)
AttributeError: 'str' object has no attribute 'resolve'
[30/Apr/2016 22:00:28] ERROR [django.request:284] Internal Server Error: /data/horses/
Traceback (most recent call last):
  File "/usr/lib/python3.5/site-packages/django/core/handlers/base.py", line 134, in get_response
    resolver_match = resolver.resolve(request.path_info)
  File "/usr/lib/python3.5/site-packages/django/core/urlresolvers.py", line 376, in resolve
    sub_match = pattern.resolve(new_path)
AttributeError: 'tuple' object has no attribute 'resolve'
[30/Apr/2016 22:01:03] ERROR [django.request:284] Internal Server Error: /data/horses/
Traceback (most recent call last):
  File "/usr/lib/python3.5/site-packages/django/core/handlers/base.py", line 134, in get_response
    resolver_match = resolver.resolve(request.path_info)
  File "/usr/lib/python3.5/site-packages/django/core/urlresolvers.py", line 376, in resolve
    sub_match = pattern.resolve(new_path)
AttributeError: 'str' object has no attribute 'resolve'
[30/Apr/2016 22:53:40] ERROR [django.request:284] Internal Server Error: /data/horsetrackers/1:5128-8367/
Traceback (most recent call last):
  File "/usr/lib/python3.5/site-packages/django/core/handlers/base.py", line 123, in get_response
    response = middleware_method(request)
  File "/usr/lib/python3.5/site-packages/django/middleware/locale.py", line 25, in process_request
    request, check_path=self.is_language_prefix_patterns_used)
  File "/usr/lib/python3.5/site-packages/django/utils/functional.py", line 33, in __get__
    res = instance.__dict__[self.name] = self.func(instance)
  File "/usr/lib/python3.5/site-packages/django/middleware/locale.py", line 68, in is_language_prefix_patterns_used
    for url_pattern in get_resolver(None).url_patterns:
  File "/usr/lib/python3.5/site-packages/django/utils/functional.py", line 33, in __get__
    res = instance.__dict__[self.name] = self.func(instance)
  File "/usr/lib/python3.5/site-packages/django/core/urlresolvers.py", line 417, in url_patterns
    patterns = getattr(self.urlconf_module, "urlpatterns", self.urlconf_module)
  File "/usr/lib/python3.5/site-packages/django/utils/functional.py", line 33, in __get__
    res = instance.__dict__[self.name] = self.func(instance)
  File "/usr/lib/python3.5/site-packages/django/core/urlresolvers.py", line 410, in urlconf_module
    return import_module(self.urlconf_name)
  File "/usr/lib/python3.5/importlib/__init__.py", line 126, in import_module
    return _bootstrap._gcd_import(name[level:], package, level)
  File "<frozen importlib._bootstrap>", line 986, in _gcd_import
  File "<frozen importlib._bootstrap>", line 969, in _find_and_load
  File "<frozen importlib._bootstrap>", line 958, in _find_and_load_unlocked
  File "<frozen importlib._bootstrap>", line 673, in _load_unlocked
  File "<frozen importlib._bootstrap_external>", line 662, in exec_module
  File "<frozen importlib._bootstrap>", line 222, in _call_with_frames_removed
  File "/srv/http/mundilfare/mundilfare/urls.py", line 80, in <module>
    url("^data/", include("data.urls", namespace="data")),
  File "/usr/lib/python3.5/site-packages/django/conf/urls/__init__.py", line 52, in include
    urlconf_module = import_module(urlconf_module)
  File "/usr/lib/python3.5/importlib/__init__.py", line 126, in import_module
    return _bootstrap._gcd_import(name[level:], package, level)
  File "<frozen importlib._bootstrap>", line 986, in _gcd_import
  File "<frozen importlib._bootstrap>", line 969, in _find_and_load
  File "<frozen importlib._bootstrap>", line 958, in _find_and_load_unlocked
  File "<frozen importlib._bootstrap>", line 673, in _load_unlocked
  File "<frozen importlib._bootstrap_external>", line 662, in exec_module
  File "<frozen importlib._bootstrap>", line 222, in _call_with_frames_removed
  File "/srv/http/mundilfare/data/urls.py", line 15, in <module>
    url(r'^index/$', views.IndexView.as_view(), name='index'),
AttributeError: module 'data.views' has no attribute 'IndexView'
[30/Apr/2016 22:53:41] ERROR [django.request:284] Internal Server Error: /data/horsetrackers/1:5128-8367/
Traceback (most recent call last):
  File "/usr/lib/python3.5/site-packages/django/core/handlers/base.py", line 235, in get_response
    response = middleware_method(request, response)
  File "/usr/lib/python3.5/site-packages/django/middleware/locale.py", line 55, in process_response
    if not (self.is_language_prefix_patterns_used
  File "/usr/lib/python3.5/site-packages/django/utils/functional.py", line 33, in __get__
    res = instance.__dict__[self.name] = self.func(instance)
  File "/usr/lib/python3.5/site-packages/django/middleware/locale.py", line 68, in is_language_prefix_patterns_used
    for url_pattern in get_resolver(None).url_patterns:
  File "/usr/lib/python3.5/site-packages/django/utils/functional.py", line 33, in __get__
    res = instance.__dict__[self.name] = self.func(instance)
  File "/usr/lib/python3.5/site-packages/django/core/urlresolvers.py", line 417, in url_patterns
    patterns = getattr(self.urlconf_module, "urlpatterns", self.urlconf_module)
  File "/usr/lib/python3.5/site-packages/django/utils/functional.py", line 33, in __get__
    res = instance.__dict__[self.name] = self.func(instance)
  File "/usr/lib/python3.5/site-packages/django/core/urlresolvers.py", line 410, in urlconf_module
    return import_module(self.urlconf_name)
  File "/usr/lib/python3.5/importlib/__init__.py", line 126, in import_module
    return _bootstrap._gcd_import(name[level:], package, level)
  File "<frozen importlib._bootstrap>", line 986, in _gcd_import
  File "<frozen importlib._bootstrap>", line 969, in _find_and_load
  File "<frozen importlib._bootstrap>", line 958, in _find_and_load_unlocked
  File "<frozen importlib._bootstrap>", line 673, in _load_unlocked
  File "<frozen importlib._bootstrap_external>", line 662, in exec_module
  File "<frozen importlib._bootstrap>", line 222, in _call_with_frames_removed
  File "/srv/http/mundilfare/mundilfare/urls.py", line 80, in <module>
    url("^data/", include("data.urls", namespace="data")),
  File "/usr/lib/python3.5/site-packages/django/conf/urls/__init__.py", line 52, in include
    urlconf_module = import_module(urlconf_module)
  File "/usr/lib/python3.5/importlib/__init__.py", line 126, in import_module
    return _bootstrap._gcd_import(name[level:], package, level)
  File "<frozen importlib._bootstrap>", line 986, in _gcd_import
  File "<frozen importlib._bootstrap>", line 969, in _find_and_load
  File "<frozen importlib._bootstrap>", line 958, in _find_and_load_unlocked
  File "<frozen importlib._bootstrap>", line 673, in _load_unlocked
  File "<frozen importlib._bootstrap_external>", line 662, in exec_module
  File "<frozen importlib._bootstrap>", line 222, in _call_with_frames_removed
  File "/srv/http/mundilfare/data/urls.py", line 15, in <module>
    url(r'^index/$', views.IndexView.as_view(), name='index'),
AttributeError: module 'data.views' has no attribute 'IndexView'
[30/Apr/2016 23:09:10] WARNING [django.request:182] Not Found: /admin/
[30/Apr/2016 23:13:32] WARNING [django.request:182] Not Found: /map/
[30/Apr/2016 23:13:33] WARNING [django.request:182] Not Found: /sv/map/
[30/Apr/2016 23:13:39] ERROR [django.request:284] Internal Server Error: /data/map/
Traceback (most recent call last):
  File "/usr/lib/python3.5/site-packages/django/core/handlers/base.py", line 149, in get_response
    response = self.process_exception_by_middleware(e, request)
  File "/usr/lib/python3.5/site-packages/django/core/handlers/base.py", line 147, in get_response
    response = wrapped_callback(request, *callback_args, **callback_kwargs)
  File "/usr/lib/python3.5/site-packages/django/contrib/auth/decorators.py", line 23, in _wrapped_view
    return view_func(request, *args, **kwargs)
TypeError: googlemap_intensity() missing 1 required positional argument: 'trackerID'
[30/Apr/2016 23:15:09] ERROR [django.request:284] Internal Server Error: /data/map/1:5128-8367/
Traceback (most recent call last):
  File "/usr/lib/python3.5/site-packages/django/core/handlers/base.py", line 149, in get_response
    response = self.process_exception_by_middleware(e, request)
  File "/usr/lib/python3.5/site-packages/django/core/handlers/base.py", line 147, in get_response
    response = wrapped_callback(request, *callback_args, **callback_kwargs)
  File "/usr/lib/python3.5/site-packages/django/contrib/auth/decorators.py", line 23, in _wrapped_view
    return view_func(request, *args, **kwargs)
  File "/srv/http/mundilfare/data/views.py", line 162, in googlemap_intensity
    cur = g.db.execute('select latitude, longitude, value4 from positions ' )
NameError: name 'g' is not defined
[30/Apr/2016 23:15:41] ERROR [django.request:284] Internal Server Error: /data/map/1:5128-8367/
Traceback (most recent call last):
  File "/usr/lib/python3.5/site-packages/django/core/handlers/base.py", line 149, in get_response
    response = self.process_exception_by_middleware(e, request)
  File "/usr/lib/python3.5/site-packages/django/core/handlers/base.py", line 147, in get_response
    response = wrapped_callback(request, *callback_args, **callback_kwargs)
  File "/usr/lib/python3.5/site-packages/django/contrib/auth/decorators.py", line 23, in _wrapped_view
    return view_func(request, *args, **kwargs)
  File "/srv/http/mundilfare/data/views.py", line 170, in googlemap_intensity
    latitude = horsedata.objects.get('latitude')
AttributeError: 'QuerySet' object has no attribute 'objects'
[30/Apr/2016 23:16:30] ERROR [django.request:284] Internal Server Error: /data/map/1:5128-8367/
Traceback (most recent call last):
  File "/usr/lib/python3.5/site-packages/django/core/handlers/base.py", line 149, in get_response
    response = self.process_exception_by_middleware(e, request)
  File "/usr/lib/python3.5/site-packages/django/core/handlers/base.py", line 147, in get_response
    response = wrapped_callback(request, *callback_args, **callback_kwargs)
  File "/usr/lib/python3.5/site-packages/django/contrib/auth/decorators.py", line 23, in _wrapped_view
    return view_func(request, *args, **kwargs)
  File "/srv/http/mundilfare/data/views.py", line 170, in googlemap_intensity
    latitude = horsedata.latitude
AttributeError: 'QuerySet' object has no attribute 'latitude'
[30/Apr/2016 23:16:51] ERROR [django.request:284] Internal Server Error: /data/map/1:5128-8367/
Traceback (most recent call last):
  File "/usr/lib/python3.5/site-packages/django/core/handlers/base.py", line 149, in get_response
    response = self.process_exception_by_middleware(e, request)
  File "/usr/lib/python3.5/site-packages/django/core/handlers/base.py", line 147, in get_response
    response = wrapped_callback(request, *callback_args, **callback_kwargs)
  File "/usr/lib/python3.5/site-packages/django/contrib/auth/decorators.py", line 23, in _wrapped_view
    return view_func(request, *args, **kwargs)
  File "/srv/http/mundilfare/data/views.py", line 170, in googlemap_intensity
    latitude = horsedata.objects.latitude
AttributeError: 'QuerySet' object has no attribute 'objects'
[30/Apr/2016 23:23:06] ERROR [django.request:284] Internal Server Error: /data/map/1:5128-8367/
Traceback (most recent call last):
  File "/usr/lib/python3.5/site-packages/django/core/handlers/base.py", line 149, in get_response
    response = self.process_exception_by_middleware(e, request)
  File "/usr/lib/python3.5/site-packages/django/core/handlers/base.py", line 147, in get_response
    response = wrapped_callback(request, *callback_args, **callback_kwargs)
  File "/usr/lib/python3.5/site-packages/django/contrib/auth/decorators.py", line 23, in _wrapped_view
    return view_func(request, *args, **kwargs)
  File "/srv/http/mundilfare/data/views.py", line 170, in googlemap_intensity
    latitude = horsedata.objects.values('latitude')
AttributeError: 'QuerySet' object has no attribute 'objects'
[30/Apr/2016 23:23:58] ERROR [django.request:284] Internal Server Error: /data/map/1:5128-8367/
Traceback (most recent call last):
  File "/usr/lib/python3.5/site-packages/django/core/handlers/base.py", line 149, in get_response
    response = self.process_exception_by_middleware(e, request)
  File "/usr/lib/python3.5/site-packages/django/core/handlers/base.py", line 147, in get_response
    response = wrapped_callback(request, *callback_args, **callback_kwargs)
  File "/usr/lib/python3.5/site-packages/django/contrib/auth/decorators.py", line 23, in _wrapped_view
    return view_func(request, *args, **kwargs)
  File "/srv/http/mundilfare/data/views.py", line 175, in googlemap_intensity
    width = int( (max(latitude)-min(latitude) )*10000)
TypeError: unorderable types: dict() > dict()
[30/Apr/2016 23:35:59] ERROR [django.request:284] Internal Server Error: /data/map/1:5128-8367/
Traceback (most recent call last):
  File "/usr/lib/python3.5/site-packages/django/core/handlers/base.py", line 149, in get_response
    response = self.process_exception_by_middleware(e, request)
  File "/usr/lib/python3.5/site-packages/django/core/handlers/base.py", line 147, in get_response
    response = wrapped_callback(request, *callback_args, **callback_kwargs)
  File "/usr/lib/python3.5/site-packages/django/contrib/auth/decorators.py", line 23, in _wrapped_view
    return view_func(request, *args, **kwargs)
  File "/srv/http/mundilfare/data/views.py", line 191, in googlemap_intensity
    latScaleFactor=math.ceil(1.0/math.sin(math.radians( max(latitude_list)) ))
NameError: name 'math' is not defined
[30/Apr/2016 23:36:20] ERROR [django.request:284] Internal Server Error: /data/map/1:5128-8367/
Traceback (most recent call last):
  File "/usr/lib/python3.5/site-packages/django/core/handlers/base.py", line 149, in get_response
    response = self.process_exception_by_middleware(e, request)
  File "/usr/lib/python3.5/site-packages/django/core/handlers/base.py", line 147, in get_response
    response = wrapped_callback(request, *callback_args, **callback_kwargs)
  File "/usr/lib/python3.5/site-packages/django/contrib/auth/decorators.py", line 23, in _wrapped_view
    return view_func(request, *args, **kwargs)
  File "/srv/http/mundilfare/data/views.py", line 201, in googlemap_intensity
    x0 = int(float(posData[i][1])*100000)
NameError: name 'posData' is not defined
[30/Apr/2016 23:37:15] ERROR [django.request:284] Internal Server Error: /data/map/1:5128-8367/
Traceback (most recent call last):
  File "/usr/lib/python3.5/site-packages/django/core/handlers/base.py", line 149, in get_response
    response = self.process_exception_by_middleware(e, request)
  File "/usr/lib/python3.5/site-packages/django/core/handlers/base.py", line 147, in get_response
    response = wrapped_callback(request, *callback_args, **callback_kwargs)
  File "/usr/lib/python3.5/site-packages/django/contrib/auth/decorators.py", line 23, in _wrapped_view
    return view_func(request, *args, **kwargs)
  File "/srv/http/mundilfare/data/views.py", line 212, in googlemap_intensity
    return render(request, 'googlemap_intensity.html', {'horsetrackers': horsetrackers, 'horsedatas': horsedata, 'points': points})
NameError: name 'horsetrackers' is not defined
[30/Apr/2016 23:38:59] ERROR [django.request:284] Internal Server Error: /data/map/1:5128-8367/
Traceback (most recent call last):
  File "/usr/lib/python3.5/site-packages/django/core/handlers/base.py", line 149, in get_response
    response = self.process_exception_by_middleware(e, request)
  File "/usr/lib/python3.5/site-packages/django/core/handlers/base.py", line 147, in get_response
    response = wrapped_callback(request, *callback_args, **callback_kwargs)
  File "/usr/lib/python3.5/site-packages/django/contrib/auth/decorators.py", line 23, in _wrapped_view
    return view_func(request, *args, **kwargs)
  File "/srv/http/mundilfare/data/views.py", line 212, in googlemap_intensity
    return render(request, 'googlemap_intensity.html', {'horsetracker': horsetracker, 'horsedatas': horsedata, 'points': points})
  File "/usr/lib/python3.5/site-packages/django/shortcuts.py", line 67, in render
    template_name, context, request=request, using=using)
  File "/usr/lib/python3.5/site-packages/django/template/loader.py", line 96, in render_to_string
    template = get_template(template_name, using=using)
  File "/usr/lib/python3.5/site-packages/django/template/loader.py", line 32, in get_template
    return engine.get_template(template_name, dirs)
  File "/usr/lib/python3.5/site-packages/django/template/backends/django.py", line 40, in get_template
    return Template(self.engine.get_template(template_name, dirs), self)
  File "/usr/lib/python3.5/site-packages/django/template/engine.py", line 190, in get_template
    template, origin = self.find_template(template_name, dirs)
  File "/usr/lib/python3.5/site-packages/django/template/engine.py", line 157, in find_template
    name, template_dirs=dirs, skip=skip,
  File "/usr/lib/python3.5/site-packages/django/template/loaders/base.py", line 46, in get_template
    contents, origin, origin.template_name, self.engine,
  File "/usr/lib/python3.5/site-packages/django/template/base.py", line 189, in __init__
    self.nodelist = self.compile_nodelist()
  File "/usr/lib/python3.5/site-packages/django/template/base.py", line 231, in compile_nodelist
    return parser.parse()
  File "/usr/lib/python3.5/site-packages/django/template/base.py", line 516, in parse
    raise self.error(token, e)
  File "/usr/lib/python3.5/site-packages/django/template/base.py", line 514, in parse
    compiled_result = compile_func(self, token)
  File "/usr/lib/python3.5/site-packages/django/template/loader_tags.py", line 267, in do_extends
    nodelist = parser.parse()
  File "/usr/lib/python3.5/site-packages/django/template/base.py", line 516, in parse
    raise self.error(token, e)
  File "/usr/lib/python3.5/site-packages/django/template/base.py", line 514, in parse
    compiled_result = compile_func(self, token)
  File "/usr/lib/python3.5/site-packages/django/template/loader_tags.py", line 241, in do_block
    nodelist = parser.parse(('endblock',))
  File "/usr/lib/python3.5/site-packages/django/template/base.py", line 487, in parse
    raise self.error(token, e)
  File "/usr/lib/python3.5/site-packages/django/template/base.py", line 485, in parse
    filter_expression = self.compile_filter(token.contents)
  File "/usr/lib/python3.5/site-packages/django/template/base.py", line 601, in compile_filter
    return FilterExpression(token, self)
  File "/usr/lib/python3.5/site-packages/django/template/base.py", line 701, in __init__
    "from '%s'" % (token[upto:], token))
django.template.exceptions.TemplateSyntaxError: Could not parse the remainder: '[0].latitude' from 'points[0].latitude'
[01/May/2016 00:16:55] ERROR [django.request:284] Internal Server Error: /data/map/1:5128-8367/
Traceback (most recent call last):
  File "/usr/lib/python3.5/site-packages/django/core/handlers/base.py", line 149, in get_response
    response = self.process_exception_by_middleware(e, request)
  File "/usr/lib/python3.5/site-packages/django/core/handlers/base.py", line 147, in get_response
    response = wrapped_callback(request, *callback_args, **callback_kwargs)
  File "/usr/lib/python3.5/site-packages/django/contrib/auth/decorators.py", line 23, in _wrapped_view
    return view_func(request, *args, **kwargs)
  File "/srv/http/mundilfare/data/views.py", line 212, in googlemap_intensity
    return render(request, 'googlemap_intensity.html', {'horsetracker': horsetracker, 'horsedatas': horsedata, 'points': points})
  File "/usr/lib/python3.5/site-packages/django/shortcuts.py", line 67, in render
    template_name, context, request=request, using=using)
  File "/usr/lib/python3.5/site-packages/django/template/loader.py", line 96, in render_to_string
    template = get_template(template_name, using=using)
  File "/usr/lib/python3.5/site-packages/django/template/loader.py", line 32, in get_template
    return engine.get_template(template_name, dirs)
  File "/usr/lib/python3.5/site-packages/django/template/backends/django.py", line 40, in get_template
    return Template(self.engine.get_template(template_name, dirs), self)
  File "/usr/lib/python3.5/site-packages/django/template/engine.py", line 190, in get_template
    template, origin = self.find_template(template_name, dirs)
  File "/usr/lib/python3.5/site-packages/django/template/engine.py", line 157, in find_template
    name, template_dirs=dirs, skip=skip,
  File "/usr/lib/python3.5/site-packages/django/template/loaders/base.py", line 46, in get_template
    contents, origin, origin.template_name, self.engine,
  File "/usr/lib/python3.5/site-packages/django/template/base.py", line 189, in __init__
    self.nodelist = self.compile_nodelist()
  File "/usr/lib/python3.5/site-packages/django/template/base.py", line 231, in compile_nodelist
    return parser.parse()
  File "/usr/lib/python3.5/site-packages/django/template/base.py", line 516, in parse
    raise self.error(token, e)
  File "/usr/lib/python3.5/site-packages/django/template/base.py", line 514, in parse
    compiled_result = compile_func(self, token)
  File "/usr/lib/python3.5/site-packages/django/template/loader_tags.py", line 267, in do_extends
    nodelist = parser.parse()
  File "/usr/lib/python3.5/site-packages/django/template/base.py", line 516, in parse
    raise self.error(token, e)
  File "/usr/lib/python3.5/site-packages/django/template/base.py", line 514, in parse
    compiled_result = compile_func(self, token)
  File "/usr/lib/python3.5/site-packages/django/template/loader_tags.py", line 241, in do_block
    nodelist = parser.parse(('endblock',))
  File "/usr/lib/python3.5/site-packages/django/template/base.py", line 516, in parse
    raise self.error(token, e)
  File "/usr/lib/python3.5/site-packages/django/template/base.py", line 514, in parse
    compiled_result = compile_func(self, token)
  File "/usr/lib/python3.5/site-packages/mezzanine/template/__init__.py", line 88, in tag_wrapper
    return ToEndTagNode()
  File "/usr/lib/python3.5/site-packages/mezzanine/template/__init__.py", line 81, in __init__
    self.nodelist = parser.parse((end_name,))
  File "/usr/lib/python3.5/site-packages/django/template/base.py", line 521, in parse
    self.unclosed_block_tag(parse_until)
  File "/usr/lib/python3.5/site-packages/django/template/base.py", line 582, in unclosed_block_tag
    raise self.error(token, msg)
django.template.exceptions.TemplateSyntaxError: Unclosed tag on line 7: 'metablock'. Looking for one of: endmetablock.
[01/May/2016 00:17:24] ERROR [django.request:284] Internal Server Error: /data/map/1:5128-8367/
Traceback (most recent call last):
  File "/usr/lib/python3.5/site-packages/django/core/handlers/base.py", line 149, in get_response
    response = self.process_exception_by_middleware(e, request)
  File "/usr/lib/python3.5/site-packages/django/core/handlers/base.py", line 147, in get_response
    response = wrapped_callback(request, *callback_args, **callback_kwargs)
  File "/usr/lib/python3.5/site-packages/django/contrib/auth/decorators.py", line 23, in _wrapped_view
    return view_func(request, *args, **kwargs)
  File "/srv/http/mundilfare/data/views.py", line 212, in googlemap_intensity
    return render(request, 'googlemap_intensity.html', {'horsetracker': horsetracker, 'horsedatas': horsedata, 'points': points})
  File "/usr/lib/python3.5/site-packages/django/shortcuts.py", line 67, in render
    template_name, context, request=request, using=using)
  File "/usr/lib/python3.5/site-packages/django/template/loader.py", line 96, in render_to_string
    template = get_template(template_name, using=using)
  File "/usr/lib/python3.5/site-packages/django/template/loader.py", line 32, in get_template
    return engine.get_template(template_name, dirs)
  File "/usr/lib/python3.5/site-packages/django/template/backends/django.py", line 40, in get_template
    return Template(self.engine.get_template(template_name, dirs), self)
  File "/usr/lib/python3.5/site-packages/django/template/engine.py", line 190, in get_template
    template, origin = self.find_template(template_name, dirs)
  File "/usr/lib/python3.5/site-packages/django/template/engine.py", line 157, in find_template
    name, template_dirs=dirs, skip=skip,
  File "/usr/lib/python3.5/site-packages/django/template/loaders/base.py", line 46, in get_template
    contents, origin, origin.template_name, self.engine,
  File "/usr/lib/python3.5/site-packages/django/template/base.py", line 189, in __init__
    self.nodelist = self.compile_nodelist()
  File "/usr/lib/python3.5/site-packages/django/template/base.py", line 231, in compile_nodelist
    return parser.parse()
  File "/usr/lib/python3.5/site-packages/django/template/base.py", line 516, in parse
    raise self.error(token, e)
  File "/usr/lib/python3.5/site-packages/django/template/base.py", line 514, in parse
    compiled_result = compile_func(self, token)
  File "/usr/lib/python3.5/site-packages/django/template/loader_tags.py", line 267, in do_extends
    nodelist = parser.parse()
  File "/usr/lib/python3.5/site-packages/django/template/base.py", line 516, in parse
    raise self.error(token, e)
  File "/usr/lib/python3.5/site-packages/django/template/base.py", line 514, in parse
    compiled_result = compile_func(self, token)
  File "/usr/lib/python3.5/site-packages/django/template/loader_tags.py", line 241, in do_block
    nodelist = parser.parse(('endblock',))
  File "/usr/lib/python3.5/site-packages/django/template/base.py", line 516, in parse
    raise self.error(token, e)
  File "/usr/lib/python3.5/site-packages/django/template/base.py", line 514, in parse
    compiled_result = compile_func(self, token)
  File "/usr/lib/python3.5/site-packages/mezzanine/template/__init__.py", line 88, in tag_wrapper
    return ToEndTagNode()
  File "/usr/lib/python3.5/site-packages/mezzanine/template/__init__.py", line 81, in __init__
    self.nodelist = parser.parse((end_name,))
  File "/usr/lib/python3.5/site-packages/django/template/base.py", line 521, in parse
    self.unclosed_block_tag(parse_until)
  File "/usr/lib/python3.5/site-packages/django/template/base.py", line 582, in unclosed_block_tag
    raise self.error(token, msg)
django.template.exceptions.TemplateSyntaxError: Unclosed tag on line 7: 'metablock'. Looking for one of: endmetablock.
[01/May/2016 00:47:24] ERROR [django.request:284] Internal Server Error: /data/map/1:5128-8367/
Traceback (most recent call last):
  File "/usr/lib/python3.5/site-packages/django/core/handlers/base.py", line 149, in get_response
    response = self.process_exception_by_middleware(e, request)
  File "/usr/lib/python3.5/site-packages/django/core/handlers/base.py", line 147, in get_response
    response = wrapped_callback(request, *callback_args, **callback_kwargs)
  File "/usr/lib/python3.5/site-packages/django/contrib/auth/decorators.py", line 23, in _wrapped_view
    return view_func(request, *args, **kwargs)
  File "/srv/http/mundilfare/data/views.py", line 212, in googlemap_intensity
    return render(request, 'googlemap_intensity.html', {'horsetracker': horsetracker, 'horsedatas': horsedata, 'points': points})
  File "/usr/lib/python3.5/site-packages/django/shortcuts.py", line 67, in render
    template_name, context, request=request, using=using)
  File "/usr/lib/python3.5/site-packages/django/template/loader.py", line 96, in render_to_string
    template = get_template(template_name, using=using)
  File "/usr/lib/python3.5/site-packages/django/template/loader.py", line 32, in get_template
    return engine.get_template(template_name, dirs)
  File "/usr/lib/python3.5/site-packages/django/template/backends/django.py", line 40, in get_template
    return Template(self.engine.get_template(template_name, dirs), self)
  File "/usr/lib/python3.5/site-packages/django/template/engine.py", line 190, in get_template
    template, origin = self.find_template(template_name, dirs)
  File "/usr/lib/python3.5/site-packages/django/template/engine.py", line 157, in find_template
    name, template_dirs=dirs, skip=skip,
  File "/usr/lib/python3.5/site-packages/django/template/loaders/base.py", line 46, in get_template
    contents, origin, origin.template_name, self.engine,
  File "/usr/lib/python3.5/site-packages/django/template/base.py", line 189, in __init__
    self.nodelist = self.compile_nodelist()
  File "/usr/lib/python3.5/site-packages/django/template/base.py", line 231, in compile_nodelist
    return parser.parse()
  File "/usr/lib/python3.5/site-packages/django/template/base.py", line 516, in parse
    raise self.error(token, e)
  File "/usr/lib/python3.5/site-packages/django/template/base.py", line 514, in parse
    compiled_result = compile_func(self, token)
  File "/usr/lib/python3.5/site-packages/django/template/loader_tags.py", line 267, in do_extends
    nodelist = parser.parse()
  File "/usr/lib/python3.5/site-packages/django/template/base.py", line 516, in parse
    raise self.error(token, e)
  File "/usr/lib/python3.5/site-packages/django/template/base.py", line 514, in parse
    compiled_result = compile_func(self, token)
  File "/usr/lib/python3.5/site-packages/django/template/loader_tags.py", line 241, in do_block
    nodelist = parser.parse(('endblock',))
  File "/usr/lib/python3.5/site-packages/django/template/base.py", line 487, in parse
    raise self.error(token, e)
  File "/usr/lib/python3.5/site-packages/django/template/base.py", line 485, in parse
    filter_expression = self.compile_filter(token.contents)
  File "/usr/lib/python3.5/site-packages/django/template/base.py", line 601, in compile_filter
    return FilterExpression(token, self)
  File "/usr/lib/python3.5/site-packages/django/template/base.py", line 701, in __init__
    "from '%s'" % (token[upto:], token))
django.template.exceptions.TemplateSyntaxError: Could not parse the remainder: '.latiude' from 'points|last.latiude'
[01/May/2016 00:47:54] ERROR [django.request:284] Internal Server Error: /data/map/1:5128-8367/
Traceback (most recent call last):
  File "/usr/lib/python3.5/site-packages/django/core/handlers/base.py", line 149, in get_response
    response = self.process_exception_by_middleware(e, request)
  File "/usr/lib/python3.5/site-packages/django/core/handlers/base.py", line 147, in get_response
    response = wrapped_callback(request, *callback_args, **callback_kwargs)
  File "/usr/lib/python3.5/site-packages/django/contrib/auth/decorators.py", line 23, in _wrapped_view
    return view_func(request, *args, **kwargs)
  File "/srv/http/mundilfare/data/views.py", line 212, in googlemap_intensity
    return render(request, 'googlemap_intensity.html', {'horsetracker': horsetracker, 'horsedatas': horsedata, 'points': points})
  File "/usr/lib/python3.5/site-packages/django/shortcuts.py", line 67, in render
    template_name, context, request=request, using=using)
  File "/usr/lib/python3.5/site-packages/django/template/loader.py", line 96, in render_to_string
    template = get_template(template_name, using=using)
  File "/usr/lib/python3.5/site-packages/django/template/loader.py", line 32, in get_template
    return engine.get_template(template_name, dirs)
  File "/usr/lib/python3.5/site-packages/django/template/backends/django.py", line 40, in get_template
    return Template(self.engine.get_template(template_name, dirs), self)
  File "/usr/lib/python3.5/site-packages/django/template/engine.py", line 190, in get_template
    template, origin = self.find_template(template_name, dirs)
  File "/usr/lib/python3.5/site-packages/django/template/engine.py", line 157, in find_template
    name, template_dirs=dirs, skip=skip,
  File "/usr/lib/python3.5/site-packages/django/template/loaders/base.py", line 46, in get_template
    contents, origin, origin.template_name, self.engine,
  File "/usr/lib/python3.5/site-packages/django/template/base.py", line 189, in __init__
    self.nodelist = self.compile_nodelist()
  File "/usr/lib/python3.5/site-packages/django/template/base.py", line 231, in compile_nodelist
    return parser.parse()
  File "/usr/lib/python3.5/site-packages/django/template/base.py", line 516, in parse
    raise self.error(token, e)
  File "/usr/lib/python3.5/site-packages/django/template/base.py", line 514, in parse
    compiled_result = compile_func(self, token)
  File "/usr/lib/python3.5/site-packages/django/template/loader_tags.py", line 267, in do_extends
    nodelist = parser.parse()
  File "/usr/lib/python3.5/site-packages/django/template/base.py", line 516, in parse
    raise self.error(token, e)
  File "/usr/lib/python3.5/site-packages/django/template/base.py", line 514, in parse
    compiled_result = compile_func(self, token)
  File "/usr/lib/python3.5/site-packages/django/template/loader_tags.py", line 241, in do_block
    nodelist = parser.parse(('endblock',))
  File "/usr/lib/python3.5/site-packages/django/template/base.py", line 487, in parse
    raise self.error(token, e)
  File "/usr/lib/python3.5/site-packages/django/template/base.py", line 485, in parse
    filter_expression = self.compile_filter(token.contents)
  File "/usr/lib/python3.5/site-packages/django/template/base.py", line 601, in compile_filter
    return FilterExpression(token, self)
  File "/usr/lib/python3.5/site-packages/django/template/base.py", line 674, in __init__
    token[start:]))
django.template.exceptions.TemplateSyntaxError: Could not parse some characters: |(points||last).latitude
[01/May/2016 00:48:20] WARNING [django.request:182] Not Found: /data/map/
[01/May/2016 00:48:20] WARNING [django.request:182] Not Found: /sv/data/map/
[01/May/2016 00:49:04] ERROR [django.request:284] Internal Server Error: /data/map/1:5128-8367/
Traceback (most recent call last):
  File "/usr/lib/python3.5/site-packages/django/core/handlers/base.py", line 149, in get_response
    response = self.process_exception_by_middleware(e, request)
  File "/usr/lib/python3.5/site-packages/django/core/handlers/base.py", line 147, in get_response
    response = wrapped_callback(request, *callback_args, **callback_kwargs)
  File "/usr/lib/python3.5/site-packages/django/contrib/auth/decorators.py", line 23, in _wrapped_view
    return view_func(request, *args, **kwargs)
  File "/srv/http/mundilfare/data/views.py", line 212, in googlemap_intensity
    return render(request, 'googlemap_intensity.html', {'horsetracker': horsetracker, 'horsedatas': horsedata, 'points': points})
  File "/usr/lib/python3.5/site-packages/django/shortcuts.py", line 67, in render
    template_name, context, request=request, using=using)
  File "/usr/lib/python3.5/site-packages/django/template/loader.py", line 96, in render_to_string
    template = get_template(template_name, using=using)
  File "/usr/lib/python3.5/site-packages/django/template/loader.py", line 32, in get_template
    return engine.get_template(template_name, dirs)
  File "/usr/lib/python3.5/site-packages/django/template/backends/django.py", line 40, in get_template
    return Template(self.engine.get_template(template_name, dirs), self)
  File "/usr/lib/python3.5/site-packages/django/template/engine.py", line 190, in get_template
    template, origin = self.find_template(template_name, dirs)
  File "/usr/lib/python3.5/site-packages/django/template/engine.py", line 157, in find_template
    name, template_dirs=dirs, skip=skip,
  File "/usr/lib/python3.5/site-packages/django/template/loaders/base.py", line 46, in get_template
    contents, origin, origin.template_name, self.engine,
  File "/usr/lib/python3.5/site-packages/django/template/base.py", line 189, in __init__
    self.nodelist = self.compile_nodelist()
  File "/usr/lib/python3.5/site-packages/django/template/base.py", line 231, in compile_nodelist
    return parser.parse()
  File "/usr/lib/python3.5/site-packages/django/template/base.py", line 516, in parse
    raise self.error(token, e)
  File "/usr/lib/python3.5/site-packages/django/template/base.py", line 514, in parse
    compiled_result = compile_func(self, token)
  File "/usr/lib/python3.5/site-packages/django/template/loader_tags.py", line 267, in do_extends
    nodelist = parser.parse()
  File "/usr/lib/python3.5/site-packages/django/template/base.py", line 516, in parse
    raise self.error(token, e)
  File "/usr/lib/python3.5/site-packages/django/template/base.py", line 514, in parse
    compiled_result = compile_func(self, token)
  File "/usr/lib/python3.5/site-packages/django/template/loader_tags.py", line 241, in do_block
    nodelist = parser.parse(('endblock',))
  File "/usr/lib/python3.5/site-packages/django/template/base.py", line 487, in parse
    raise self.error(token, e)
  File "/usr/lib/python3.5/site-packages/django/template/base.py", line 485, in parse
    filter_expression = self.compile_filter(token.contents)
  File "/usr/lib/python3.5/site-packages/django/template/base.py", line 601, in compile_filter
    return FilterExpression(token, self)
  File "/usr/lib/python3.5/site-packages/django/template/base.py", line 674, in __init__
    token[start:]))
django.template.exceptions.TemplateSyntaxError: Could not parse some characters: |{points||last}.latitude
[01/May/2016 00:49:20] ERROR [django.request:284] Internal Server Error: /data/map/1:5128-8367/
Traceback (most recent call last):
  File "/usr/lib/python3.5/site-packages/django/core/handlers/base.py", line 149, in get_response
    response = self.process_exception_by_middleware(e, request)
  File "/usr/lib/python3.5/site-packages/django/core/handlers/base.py", line 147, in get_response
    response = wrapped_callback(request, *callback_args, **callback_kwargs)
  File "/usr/lib/python3.5/site-packages/django/contrib/auth/decorators.py", line 23, in _wrapped_view
    return view_func(request, *args, **kwargs)
  File "/srv/http/mundilfare/data/views.py", line 212, in googlemap_intensity
    return render(request, 'googlemap_intensity.html', {'horsetracker': horsetracker, 'horsedatas': horsedata, 'points': points})
  File "/usr/lib/python3.5/site-packages/django/shortcuts.py", line 67, in render
    template_name, context, request=request, using=using)
  File "/usr/lib/python3.5/site-packages/django/template/loader.py", line 96, in render_to_string
    template = get_template(template_name, using=using)
  File "/usr/lib/python3.5/site-packages/django/template/loader.py", line 32, in get_template
    return engine.get_template(template_name, dirs)
  File "/usr/lib/python3.5/site-packages/django/template/backends/django.py", line 40, in get_template
    return Template(self.engine.get_template(template_name, dirs), self)
  File "/usr/lib/python3.5/site-packages/django/template/engine.py", line 190, in get_template
    template, origin = self.find_template(template_name, dirs)
  File "/usr/lib/python3.5/site-packages/django/template/engine.py", line 157, in find_template
    name, template_dirs=dirs, skip=skip,
  File "/usr/lib/python3.5/site-packages/django/template/loaders/base.py", line 46, in get_template
    contents, origin, origin.template_name, self.engine,
  File "/usr/lib/python3.5/site-packages/django/template/base.py", line 189, in __init__
    self.nodelist = self.compile_nodelist()
  File "/usr/lib/python3.5/site-packages/django/template/base.py", line 231, in compile_nodelist
    return parser.parse()
  File "/usr/lib/python3.5/site-packages/django/template/base.py", line 516, in parse
    raise self.error(token, e)
  File "/usr/lib/python3.5/site-packages/django/template/base.py", line 514, in parse
    compiled_result = compile_func(self, token)
  File "/usr/lib/python3.5/site-packages/django/template/loader_tags.py", line 267, in do_extends
    nodelist = parser.parse()
  File "/usr/lib/python3.5/site-packages/django/template/base.py", line 516, in parse
    raise self.error(token, e)
  File "/usr/lib/python3.5/site-packages/django/template/base.py", line 514, in parse
    compiled_result = compile_func(self, token)
  File "/usr/lib/python3.5/site-packages/django/template/loader_tags.py", line 241, in do_block
    nodelist = parser.parse(('endblock',))
  File "/usr/lib/python3.5/site-packages/django/template/base.py", line 487, in parse
    raise self.error(token, e)
  File "/usr/lib/python3.5/site-packages/django/template/base.py", line 485, in parse
    filter_expression = self.compile_filter(token.contents)
  File "/usr/lib/python3.5/site-packages/django/template/base.py", line 601, in compile_filter
    return FilterExpression(token, self)
  File "/usr/lib/python3.5/site-packages/django/template/base.py", line 674, in __init__
    token[start:]))
django.template.exceptions.TemplateSyntaxError: Could not parse some characters: |[points||last].latitude
[01/May/2016 00:51:37] ERROR [django.request:284] Internal Server Error: /data/map/1:5128-8367/
Traceback (most recent call last):
  File "/usr/lib/python3.5/site-packages/django/core/handlers/base.py", line 149, in get_response
    response = self.process_exception_by_middleware(e, request)
  File "/usr/lib/python3.5/site-packages/django/core/handlers/base.py", line 147, in get_response
    response = wrapped_callback(request, *callback_args, **callback_kwargs)
  File "/usr/lib/python3.5/site-packages/django/contrib/auth/decorators.py", line 23, in _wrapped_view
    return view_func(request, *args, **kwargs)
  File "/srv/http/mundilfare/data/views.py", line 212, in googlemap_intensity
    return render(request, 'googlemap_intensity.html', {'horsetracker': horsetracker, 'horsedatas': horsedata, 'points': points})
  File "/usr/lib/python3.5/site-packages/django/shortcuts.py", line 67, in render
    template_name, context, request=request, using=using)
  File "/usr/lib/python3.5/site-packages/django/template/loader.py", line 96, in render_to_string
    template = get_template(template_name, using=using)
  File "/usr/lib/python3.5/site-packages/django/template/loader.py", line 32, in get_template
    return engine.get_template(template_name, dirs)
  File "/usr/lib/python3.5/site-packages/django/template/backends/django.py", line 40, in get_template
    return Template(self.engine.get_template(template_name, dirs), self)
  File "/usr/lib/python3.5/site-packages/django/template/engine.py", line 190, in get_template
    template, origin = self.find_template(template_name, dirs)
  File "/usr/lib/python3.5/site-packages/django/template/engine.py", line 157, in find_template
    name, template_dirs=dirs, skip=skip,
  File "/usr/lib/python3.5/site-packages/django/template/loaders/base.py", line 46, in get_template
    contents, origin, origin.template_name, self.engine,
  File "/usr/lib/python3.5/site-packages/django/template/base.py", line 189, in __init__
    self.nodelist = self.compile_nodelist()
  File "/usr/lib/python3.5/site-packages/django/template/base.py", line 231, in compile_nodelist
    return parser.parse()
  File "/usr/lib/python3.5/site-packages/django/template/base.py", line 516, in parse
    raise self.error(token, e)
  File "/usr/lib/python3.5/site-packages/django/template/base.py", line 514, in parse
    compiled_result = compile_func(self, token)
  File "/usr/lib/python3.5/site-packages/django/template/loader_tags.py", line 267, in do_extends
    nodelist = parser.parse()
  File "/usr/lib/python3.5/site-packages/django/template/base.py", line 516, in parse
    raise self.error(token, e)
  File "/usr/lib/python3.5/site-packages/django/template/base.py", line 514, in parse
    compiled_result = compile_func(self, token)
  File "/usr/lib/python3.5/site-packages/django/template/loader_tags.py", line 241, in do_block
    nodelist = parser.parse(('endblock',))
  File "/usr/lib/python3.5/site-packages/django/template/base.py", line 487, in parse
    raise self.error(token, e)
  File "/usr/lib/python3.5/site-packages/django/template/base.py", line 485, in parse
    filter_expression = self.compile_filter(token.contents)
  File "/usr/lib/python3.5/site-packages/django/template/base.py", line 601, in compile_filter
    return FilterExpression(token, self)
  File "/usr/lib/python3.5/site-packages/django/template/base.py", line 701, in __init__
    "from '%s'" % (token[upto:], token))
django.template.exceptions.TemplateSyntaxError: Could not parse the remainder: '.latitude' from 'points|last.latitude'
